Workbook

Sheet Dashboard
A1: Spark Lakehouse Lab - Progress Dashboard
A2: Instacart | PostgreSQL | RustFS | Apache Iceberg | Spark 4.x standalone. All numbers on this sheet are formulas; do not type over them.
A4: HOW TO USE
A5: Yellow cells are yours to edit: Status (dropdown), Started, Completed and Evidence / notes on each checklist tab.
A6: Status values: Not started, In progress, Blocked, Done, Skipped. Skipped items are excluded from % complete.
A7: Example: set Status = Done, Completed = 2026-11-03, Evidence = 'E-014, D-003' (experiment and defect IDs).
A8: Log every experiment on Experiments (prediction first), every data issue on Defects, every choice on Decisions.
A9: Grey italic rows on the log tabs are examples: overwrite or delete them. Suggested order: Setup, P1 (M0-M5), P3 and P2, P1 (M2, M6-M8), P4, P5.
A11: OVERALL PROGRESS
A12: Scope | B12: Detail | C12: Total | D12: Done | E12: In progress | F12: Blocked | G12: Not started | H12: Skipped | I12: % complete | J12: Next task
A13: All areas | B13: Setup + five projects | C13: =SUM(C17:C22) -> 498 | D13: =SUM(D17:D22) -> 0 | E13: =SUM(E17:E22) -> 0 | F13: =SUM(F17:F22) -> 0 | G13: =SUM(G17:G22) -> 498 | H13: =SUM(H17:H22) -> 0 | I13: =IFERROR(D13/(C13-H13),0) -> 0 | J13: =D13&" of "&(C13-H13)&" items complete" -> 0 of 498 items complete
A15: BY AREA
A16: Area | B16: Open this tab | C16: Total | D16: Done | E16: In progress | F16: Blocked | G16: Not started | H16: Skipped | I16: % complete | J16: Next task (first In progress, else first Not started)
A17: Setup and gates | B17: Setup and gates (open tab) | C17: =SUM(D17:H17) -> 47 | D17: =COUNTIF(Setup!$E$6:$E$600,"Done") -> 0 | E17: =COUNTIF(Setup!$E$6:$E$600,"In progress") -> 0 | F17: =COUNTIF(Setup!$E$6:$E$600,"Blocked") -> 0 | G17: =COUNTIF(Setup!$E$6:$E$600,"Not started") -> 47 | H17: =COUNTIF(Setup!$E$6:$E$600,"Skipped") -> 0 | I17: =IFERROR(D17/(C17-H17),0) -> 0 | J17: =IFERROR(INDEX(Setup!$C$6:$C$600,MATCH("In progress",Setup!$E$6:$E$600,0)),IFERROR(INDEX(Setup!$C$6:$C$600,MATCH("Not started",Setup!$E$6:$E$600,0)),"All items complete")) -> Gate A: find the Iceberg Spark runtime artifact that matches your Spark minor version (Scala 2.13) on Maven Central. If the Spark 4.2 runtime is missing, pin Spark to the newest 4.x that has one. Record in Environment and Decisions.
A18: Project 1 | B18: Project 1: Lakehouse medallion ETL | C18: =SUM(D18:H18) -> 113 | D18: =COUNTIF(P1_ETL!$E$6:$E$600,"Done") -> 0 | E18: =COUNTIF(P1_ETL!$E$6:$E$600,"In progress") -> 0 | F18: =COUNTIF(P1_ETL!$E$6:$E$600,"Blocked") -> 0 | G18: =COUNTIF(P1_ETL!$E$6:$E$600,"Not started") -> 113 | H18: =COUNTIF(P1_ETL!$E$6:$E$600,"Skipped") -> 0 | I18: =IFERROR(D18/(C18-H18),0) -> 0 | J18: =IFERROR(INDEX(P1_ETL!$C$6:$C$600,MATCH("In progress",P1_ETL!$E$6:$E$600,0)),IFERROR(INDEX(P1_ETL!$C$6:$C$600,MATCH("Not started",P1_ETL!$E$6:$E$600,0)),"All items complete")) -> Keep an untouched copy of the raw files in landing/raw_dump (everything must be reproducible from it).
A19: Project 2 | B19: Project 2: Joins, shuffles and skew | C19: =SUM(D19:H19) -> 91 | D19: =COUNTIF(P2_Joins!$E$6:$E$600,"Done") -> 0 | E19: =COUNTIF(P2_Joins!$E$6:$E$600,"In progress") -> 0 | F19: =COUNTIF(P2_Joins!$E$6:$E$600,"Blocked") -> 0 | G19: =COUNTIF(P2_Joins!$E$6:$E$600,"Not started") -> 91 | H19: =COUNTIF(P2_Joins!$E$6:$E$600,"Skipped") -> 0 | I19: =IFERROR(D19/(C19-H19),0) -> 0 | J19: =IFERROR(INDEX(P2_Joins!$C$6:$C$600,MATCH("In progress",P2_Joins!$E$6:$E$600,0)),IFERROR(INDEX(P2_Joins!$C$6:$C$600,MATCH("Not started",P2_Joins!$E$6:$E$600,0)),"All items complete")) -> Freeze the data version: record Iceberg snapshot ids of lines, orders, products, aisles, departments, users, stores, price book, payments, events.
A20: Project 3 | B20: Project 3: Catalyst and query planning | C20: =SUM(D20:H20) -> 79 | D20: =COUNTIF(P3_Planner!$E$6:$E$600,"Done") -> 0 | E20: =COUNTIF(P3_Planner!$E$6:$E$600,"In progress") -> 0 | F20: =COUNTIF(P3_Planner!$E$6:$E$600,"Blocked") -> 0 | G20: =COUNTIF(P3_Planner!$E$6:$E$600,"Not started") -> 79 | H20: =COUNTIF(P3_Planner!$E$6:$E$600,"Skipped") -> 0 | I20: =IFERROR(D20/(C20-H20),0) -> 0 | J20: =IFERROR(INDEX(P3_Planner!$C$6:$C$600,MATCH("In progress",P3_Planner!$E$6:$E$600,0)),IFERROR(INDEX(P3_Planner!$C$6:$C$600,MATCH("Not started",P3_Planner!$E$6:$E$600,0)),"All items complete")) -> Build lines/events variants: unsorted monthly-partitioned; sorted by product; z-ordered (department, hour); unpartitioned sorted; raw Parquet copy in landing.
A21: Project 4 | B21: Project 4: Executors, memory and I/O performance | C21: =SUM(D21:H21) -> 91 | D21: =COUNTIF(P4_Perf!$E$6:$E$600,"Done") -> 0 | E21: =COUNTIF(P4_Perf!$E$6:$E$600,"In progress") -> 0 | F21: =COUNTIF(P4_Perf!$E$6:$E$600,"Blocked") -> 0 | G21: =COUNTIF(P4_Perf!$E$6:$E$600,"Not started") -> 91 | H21: =COUNTIF(P4_Perf!$E$6:$E$600,"Skipped") -> 0 | I21: =IFERROR(D21/(C21-H21),0) -> 0 | J21: =IFERROR(INDEX(P4_Perf!$C$6:$C$600,MATCH("In progress",P4_Perf!$E$6:$E$600,0)),IFERROR(INDEX(P4_Perf!$C$6:$C$600,MATCH("Not started",P4_Perf!$E$6:$E$600,0)),"All items complete")) -> Define W1-W6: scan-heavy, shuffle-heavy, CPU-heavy (per-line score), memory-heavy (cache + wide aggregation), write-heavy (layout rewrite), mixed user-feature build.
A22: Project 5 | B22: Project 5: Streaming and CDC into Iceberg | C22: =SUM(D22:H22) -> 77 | D22: =COUNTIF(P5_Streaming!$E$6:$E$600,"Done") -> 0 | E22: =COUNTIF(P5_Streaming!$E$6:$E$600,"In progress") -> 0 | F22: =COUNTIF(P5_Streaming!$E$6:$E$600,"Blocked") -> 0 | G22: =COUNTIF(P5_Streaming!$E$6:$E$600,"Not started") -> 77 | H22: =COUNTIF(P5_Streaming!$E$6:$E$600,"Skipped") -> 0 | I22: =IFERROR(D22/(C22-H22),0) -> 0 | J22: =IFERROR(INDEX(P5_Streaming!$C$6:$C$600,MATCH("In progress",P5_Streaming!$E$6:$E$600,0)),IFERROR(INDEX(P5_Streaming!$C$6:$C$600,MATCH("Not started",P5_Streaming!$E$6:$E$600,0)),"All items complete")) -> Clickstream producer around real baskets, with duplicates/replays, malformed lines, schema drift, out-of-order events and ~2% very late events.
A24: SUPPORTING TRACKERS
A25: Tracker | B25: Measure | C25: Count
A26: Experiments | B26: Logged | C26: =COUNTA(Experiments!$A$7:$A$106) -> 0
A27: Experiments | B27: Prediction correct (Yes) | C27: =COUNTIF(Experiments!$M$7:$M$106,"Yes") -> 0
A28: Experiments | B28: Prediction accuracy (Yes / answered) | C28: =IFERROR(COUNTIF(Experiments!$M$7:$M$106,"Yes")/(COUNTIF(Experiments!$M$7:$M$106,"Yes")+COUNTIF(Experiments!$M$7:$M$106,"No")+COUNTIF(Experiments!$M$7:$M$106,"Partly")),0) -> 0
A29: Defects | B29: On the register | C29: =COUNTA(Defects!$A$7:$A$60) -> 11
A30: Defects | B30: Handled | C30: =COUNTIF(Defects!$M$7:$M$60,"Handled") -> 0
A31: Defects | B31: Still to verify | C31: =COUNTIF(Defects!$M$7:$M$60,"To verify") -> 11
A32: Decisions | B32: Decided | C32: =COUNTIF(Decisions!$H$7:$H$40,"Decided") -> 0
A33: Decisions | B33: Still open | C33: =COUNTIF(Decisions!$H$7:$H$40,"Open") -> 14
A34: Config cards | B34: Learned | C34: =COUNTIF(Config_Cards!$I$6:$I$38,"Learned") -> 0
A35: Config cards | B35: Total | C35: =COUNTA(Config_Cards!$B$6:$B$38) -> 33
A37: BY MILESTONE
A38: Area | B38: Milestone | C38: Total | D38: Done | E38: In progress | F38: Blocked | G38: Not started | H38: Skipped | I38: % complete
A39: SU | B39: S0 Gates and decisions | C39: =SUM(D39:H39) -> 5 | D39: =COUNTIFS(Setup!$B$6:$B$600,$B39,Setup!$E$6:$E$600,"Done") -> 0 | E39: =COUNTIFS(Setup!$B$6:$B$600,$B39,Setup!$E$6:$E$600,"In progress") -> 0 | F39: =COUNTIFS(Setup!$B$6:$B$600,$B39,Setup!$E$6:$E$600,"Blocked") -> 0 | G39: =COUNTIFS(Setup!$B$6:$B$600,$B39,Setup!$E$6:$E$600,"Not started") -> 5 | H39: =COUNTIFS(Setup!$B$6:$B$600,$B39,Setup!$E$6:$E$600,"Skipped") -> 0 | I39: =IFERROR(D39/(C39-H39),0) -> 0
A40: SU | B40: S1 Platform bring-up | C40: =SUM(D40:H40) -> 10 | D40: =COUNTIFS(Setup!$B$6:$B$600,$B40,Setup!$E$6:$E$600,"Done") -> 0 | E40: =COUNTIFS(Setup!$B$6:$B$600,$B40,Setup!$E$6:$E$600,"In progress") -> 0 | F40: =COUNTIFS(Setup!$B$6:$B$600,$B40,Setup!$E$6:$E$600,"Blocked") -> 0 | G40: =COUNTIFS(Setup!$B$6:$B$600,$B40,Setup!$E$6:$E$600,"Not started") -> 10 | H40: =COUNTIFS(Setup!$B$6:$B$600,$B40,Setup!$E$6:$E$600,"Skipped") -> 0 | I40: =IFERROR(D40/(C40-H40),0) -> 0
A41: SU | B41: S2 RustFS smoke tests | C41: =SUM(D41:H41) -> 8 | D41: =COUNTIFS(Setup!$B$6:$B$600,$B41,Setup!$E$6:$E$600,"Done") -> 0 | E41: =COUNTIFS(Setup!$B$6:$B$600,$B41,Setup!$E$6:$E$600,"In progress") -> 0 | F41: =COUNTIFS(Setup!$B$6:$B$600,$B41,Setup!$E$6:$E$600,"Blocked") -> 0 | G41: =COUNTIFS(Setup!$B$6:$B$600,$B41,Setup!$E$6:$E$600,"Not started") -> 8 | H41: =COUNTIFS(Setup!$B$6:$B$600,$B41,Setup!$E$6:$E$600,"Skipped") -> 0 | I41: =IFERROR(D41/(C41-H41),0) -> 0
A42: SU | B42: S3 Dataset acquisition | C42: =SUM(D42:H42) -> 6 | D42: =COUNTIFS(Setup!$B$6:$B$600,$B42,Setup!$E$6:$E$600,"Done") -> 0 | E42: =COUNTIFS(Setup!$B$6:$B$600,$B42,Setup!$E$6:$E$600,"In progress") -> 0 | F42: =COUNTIFS(Setup!$B$6:$B$600,$B42,Setup!$E$6:$E$600,"Blocked") -> 0 | G42: =COUNTIFS(Setup!$B$6:$B$600,$B42,Setup!$E$6:$E$600,"Not started") -> 6 | H42: =COUNTIFS(Setup!$B$6:$B$600,$B42,Setup!$E$6:$E$600,"Skipped") -> 0 | I42: =IFERROR(D42/(C42-H42),0) -> 0
A43: SU | B43: S4 Helpers | C43: =SUM(D43:H43) -> 12 | D43: =COUNTIFS(Setup!$B$6:$B$600,$B43,Setup!$E$6:$E$600,"Done") -> 0 | E43: =COUNTIFS(Setup!$B$6:$B$600,$B43,Setup!$E$6:$E$600,"In progress") -> 0 | F43: =COUNTIFS(Setup!$B$6:$B$600,$B43,Setup!$E$6:$E$600,"Blocked") -> 0 | G43: =COUNTIFS(Setup!$B$6:$B$600,$B43,Setup!$E$6:$E$600,"Not started") -> 12 | H43: =COUNTIFS(Setup!$B$6:$B$600,$B43,Setup!$E$6:$E$600,"Skipped") -> 0 | I43: =IFERROR(D43/(C43-H43),0) -> 0
A44: SU | B44: S5 Conventions | C44: =SUM(D44:H44) -> 6 | D44: =COUNTIFS(Setup!$B$6:$B$600,$B44,Setup!$E$6:$E$600,"Done") -> 0 | E44: =COUNTIFS(Setup!$B$6:$B$600,$B44,Setup!$E$6:$E$600,"In progress") -> 0 | F44: =COUNTIFS(Setup!$B$6:$B$600,$B44,Setup!$E$6:$E$600,"Blocked") -> 0 | G44: =COUNTIFS(Setup!$B$6:$B$600,$B44,Setup!$E$6:$E$600,"Not started") -> 6 | H44: =COUNTIFS(Setup!$B$6:$B$600,$B44,Setup!$E$6:$E$600,"Skipped") -> 0 | I44: =IFERROR(D44/(C44-H44),0) -> 0
A45: P1 | B45: M0 Load, profile, enrich | C45: =SUM(D45:H45) -> 19 | D45: =COUNTIFS(P1_ETL!$B$6:$B$600,$B45,P1_ETL!$E$6:$E$600,"Done") -> 0 | E45: =COUNTIFS(P1_ETL!$B$6:$B$600,$B45,P1_ETL!$E$6:$E$600,"In progress") -> 0 | F45: =COUNTIFS(P1_ETL!$B$6:$B$600,$B45,P1_ETL!$E$6:$E$600,"Blocked") -> 0 | G45: =COUNTIFS(P1_ETL!$B$6:$B$600,$B45,P1_ETL!$E$6:$E$600,"Not started") -> 19 | H45: =COUNTIFS(P1_ETL!$B$6:$B$600,$B45,P1_ETL!$E$6:$E$600,"Skipped") -> 0 | I45: =IFERROR(D45/(C45-H45),0) -> 0
...

Sheet Setup
A1: Setup and gates
A2: Source: README sections 2-3 (bring-up and gates). Edit only the yellow cells: Status (dropdown), Started, Completed, Evidence / notes.
A3: Progress | B3: =IFERROR(COUNTIF($E$6:$E$600,"Done")/(COUNTA($E$6:$E$600)-COUNTIF($E$6:$E$600,"Skipped")),0) -> 0 | C3: =COUNTIF($E$6:$E$600,"Done")&" of "&(COUNTA($E$6:$E$600)-COUNTIF($E$6:$E$600,"Skipped"))&" items done | In progress: "&COUNTIF($E$6:$E$600,"In progress")&" | Blocked: "&COUNTIF($E$6:$E$600,"Blocked")&" | Skipped: "&COUNTIF($E$6:$E$600,"Skipped") -> 0 of 47 items done | In progress: 0 | Blocked: 0 | Skipped: 0
A5: ID | B5: Milestone | C5: Task | D5: Type | E5: Status | F5: Started | G5: Completed | H5: Evidence / notes
A6: S0 Gates and decisions
A7: SU-S0-01 | B7: S0 Gates and decisions | C7: Gate A: find the Iceberg Spark runtime artifact that matches your Spark minor version (Scala 2.13) on Maven Central. If the Spark 4.2 runtime is missing, pin Spark to the newest 4.x that has one. Record in Environment and Decisions. | D7: Task | E7: Not started
A8: SU-S0-02 | B8: S0 Gates and decisions | C8: Gate C: decide how the Iceberg runtime, the S3 access bundle (S3A + matching AWS SDK, or Iceberg AWS bundle) and the Postgres JDBC driver reach the driver and every executor (baked in vs resolved at runtime). | D8: Task | E8: Not started
A9: SU-S0-03 | B9: S0 Gates and decisions | C9: Gate D: choose the catalog (recommended: JDBC on Postgres, separate database). Record in Decisions. | D9: Task | E9: Not started
A10: SU-S0-04 | B10: S0 Gates and decisions | C10: Gate E: plan Postgres capacity for ~34M order lines (disk, memory, bulk load then index) and decide what stays in Postgres vs files only. | D10: Task | E10: Not started
A11: SU-S0-05 | B11: S0 Gates and decisions | C11: Set explicit CPU and memory limits on Postgres and RustFS (or record that you left them off on purpose). | D11: Task | E11: Not started
A12: S1 Platform bring-up
A13: SU-S1-01 | B13: S1 Platform bring-up | C13: 1. RustFS running (pinned release tag, changed credentials). Log in to the console, create buckets landing, warehouse, checkpoints, spark-events, archive; list them with an S3 client. | D13: Task | E13: Not started
A14: SU-S1-02 | B14: S1 Platform bring-up | C14: 2. PostgreSQL running with two databases (source, catalog). Connect from your laptop and from the Jupyter container. | D14: Task | E14: Not started
A15: SU-S1-03 | B15: S1 Platform bring-up | C15: 3. Spark cluster running. Master UI shows 4 workers, each with 2 cores and 2 GB. | D15: Task | E15: Not started
A16: SU-S1-04 | B16: S1 Platform bring-up | C16: 4. Jars resolved. A session starts with the Iceberg runtime, S3 access and the JDBC driver on the driver and on executors. | D16: Task | E16: Not started
A17: SU-S1-05 | B17: S1 Platform bring-up | C17: 5. Catalog configured. Create and drop a test namespace. | D17: Task | E17: Not started
A18: SU-S1-06 | B18: S1 Platform bring-up | C18: 6. Iceberg smoke test. Create a table, insert, read back, list snapshots, and see data and metadata objects in the RustFS console. | D18: Task | E18: Not started
A19: SU-S1-07 | B19: S1 Platform bring-up | C19: 7. S3A smoke test. Write and read Parquet at an s3a path and compare with Iceberg's own file I/O. | D19: Task | E19: Not started
A20: SU-S1-08 | B20: S1 Platform bring-up | C20: 8. JDBC smoke test. Read a 1M-row test table with several partitions and watch the connections in Postgres. | D20: Task | E20: Not started
A21: SU-S1-09 | B21: S1 Platform bring-up | C21: 9. History server shows a finished application with its event log in the bucket. | D21: Task | E21: Not started
A22: SU-S1-10 | B22: S1 Platform bring-up | C22: 10. End-to-end hello pipeline: Postgres -> landing Parquet -> Iceberg bronze -> query. Run twice; the second run must be idempotent. | D22: Task | E22: Not started
A23: S2 RustFS smoke tests
A24: SU-S2-01 | B24: S2 RustFS smoke tests | C24: Write and read a Parquet file through both S3A and Iceberg file I/O. | D24: Experiment | E24: Not started
A25: SU-S2-02 | B25: S2 RustFS smoke tests | C25: Write an object larger than the multipart threshold. | D25: Experiment | E25: Not started
A26: SU-S2-03 | B26: S2 RustFS smoke tests | C26: List a prefix with 10k+ objects (note time and pagination). | D26: Experiment | E26: Not started
A27: SU-S2-04 | B27: S2 RustFS smoke tests | C27: Delete many objects (cleanup and orphan removal path). | D27: Experiment | E27: Not started
A28: SU-S2-05 | B28: S2 RustFS smoke tests | C28: Two Spark applications writing at once. | D28: Experiment | E28: Not started
A29: SU-S2-06 | B29: S2 RustFS smoke tests | C29: Read an Iceberg table's metadata tables. | D29: Experiment | E29: Not started
A30: SU-S2-07 | B30: S2 RustFS smoke tests | C30: Kill RustFS during a write, restart, verify table and objects. | D30: Experiment | E30: Not started
A31: SU-S2-08 | B31: S2 RustFS smoke tests | C31: Smoke-test results recorded; every difference from AWS S3 behavior noted. | D31: Exit check | E31: Not started
A32: S3 Dataset acquisition
A33: SU-S3-01 | B33: S3 Dataset acquisition | C33: Create a Kaggle account and accept the Instacart competition rules so the files unlock. | D33: Task | E33: Not started
A34: SU-S3-02 | B34: S3 Dataset acquisition | C34: Read the dataset terms (learning use only; keep your copy out of shared repositories). | D34: Task | E34: Not started
A35: SU-S3-03 | B35: S3 Dataset acquisition | C35: Download all files and record checksums. | D35: Task | E35: Not started
A36: SU-S3-04 | B36: S3 Dataset acquisition | C36: Store an immutable copy under landing/raw_dump. | D36: Task | E36: Not started
A37: SU-S3-05 | B37: S3 Dataset acquisition | C37: Record file sizes and plain line counts (your first reconciliation numbers). | D37: Task | E37: Not started
A38: SU-S3-06 | B38: S3 Dataset acquisition | C38: Raw files stored untouched, with checksums and line counts written down. | D38: Exit check | E38: Not started
A39: S4 Helpers
A40: SU-S4-01 | B40: S4 Helpers | C40: Dataset loader (stage as text, type, constrain, log violations to the defect register). | D40: Task | E40: Not started
A41: SU-S4-02 | B41: S4 Helpers | C41: Timeline builder (rebuild timestamps from gaps, hours, weekdays; report inconsistencies). | D41: Task | E41: Not started
...

Sheet P1_ETL
A1: Project 1: Lakehouse medallion ETL
A2: Source: 01-lakehouse-medallion-etl.md. Edit only the yellow cells: Status (dropdown), Started, Completed, Evidence / notes.
A3: Progress | B3: =IFERROR(COUNTIF($E$6:$E$600,"Done")/(COUNTA($E$6:$E$600)-COUNTIF($E$6:$E$600,"Skipped")),0) -> 0 | C3: =COUNTIF($E$6:$E$600,"Done")&" of "&(COUNTA($E$6:$E$600)-COUNTIF($E$6:$E$600,"Skipped"))&" items done | In progress: "&COUNTIF($E$6:$E$600,"In progress")&" | Blocked: "&COUNTIF($E$6:$E$600,"Blocked")&" | Skipped: "&COUNTIF($E$6:$E$600,"Skipped") -> 0 of 113 items done | In progress: 0 | Blocked: 0 | Skipped: 0
A5: ID | B5: Milestone | C5: Task | D5: Type | E5: Status | F5: Started | G5: Completed | H5: Evidence / notes
A6: M0 Load, profile, enrich
A7: P1-M0-01 | B7: M0 Load, profile, enrich | C7: Keep an untouched copy of the raw files in landing/raw_dump (everything must be reproducible from it). | D7: Task | E7: Not started
A8: P1-M0-02 | B8: M0 Load, profile, enrich | C8: Create a staging schema with every column as text; load all files; note rows per second for each loading method. | D8: Task | E8: Not started
A9: P1-M0-03 | B9: M0 Load, profile, enrich | C9: Fix CSV parsing of product names (commas, quotes): naive reader vs quoted-CSV reader; log the broken-row count as a defect. | D9: Task | E9: Not started
A10: P1-M0-04 | B10: M0 Load, profile, enrich | C10: Type the data in a second step; capture every row that fails to cast. | D10: Task | E10: Not started
A11: P1-M0-05 | B11: M0 Load, profile, enrich | C11: Profile every table: row count, null rate, distinct counts, min/max, text lengths, top values, duplicate rate on candidate keys. | D11: Task | E11: Not started
A12: P1-M0-06 | B12: M0 Load, profile, enrich | C12: Profile relationships (orphan counts per candidate foreign key, cardinality), distributions (basket size, orders per user, product frequency, hour/weekday) and temporal fields (days_since_prior_order, spike at the cap, nulls by order_number). | D12: Task | E12: Not started
A13: P1-M0-07 | B13: M0 Load, profile, enrich | C13: Union prior and train lines into one table with a source-file column; decide and record how test-set orders (no lines) are represented. | D13: Task | E13: Not started
A14: P1-M0-08 | B14: M0 Load, profile, enrich | C14: Add constraints in stages (PKs on small tables and orders, composite PK on lines, FKs lines->orders/products, products->aisles/departments); fill the constraint status table with violation counts. | D14: Task | E14: Not started
A15: P1-M0-09 | B15: M0 Load, profile, enrich | C15: Verify the reordered flag against each user's history; interpret mismatches. | D15: Task | E15: Not started
A16: P1-M0-10 | B16: M0 Load, profile, enrich | C16: Build the rebuilt timeline (start date, first order, capped gaps, weekday mismatch rules); output timestamp and quality flag; report the weekday-fit rate. | D16: Task | E16: Not started
A17: P1-M0-11 | B17: M0 Load, profile, enrich | C17: Generate synthetic tables in dependency order: users, stores, price book, totals, payments, lifecycle, erasures, campaign calendar; test each with its validity rules. | D17: Task | E17: Not started
A18: P1-M0-12 | B18: M0 Load, profile, enrich | C18: Add updated_at and is_deleted, keys and FK indexes; deliberately skip one useful index (for example on the order timestamp). | D18: Task | E18: Not started
... A25: P1-M0-19 | B25: M0 Load, profile, enrich | C25: Defect register covers every issue in README section 3.3; constraint table complete; timeline report written; S and M row counts match the files. | D25: Exit check | E25: Not started
A26: M1 Full extraction
A27: P1-M1-01 | B27: M1 Full extraction | C27: Choose the snapshot-consistency approach per table (shared repeatable-read snapshot, quiet window, or accept and reconcile). | D27: Task | E27: Not started
A28: P1-M1-02 | B28: M1 Full extraction | C28: Choose a partitioning strategy per table (id ranges, hash, month, surrogate key); get bounds from a min/max query just before the run. | D28: Task | E28: Not started
A29: P1-M1-03 | B29: M1 Full extraction | C29: Measure rows per partition before the full run (large baskets make equal id ranges unequal). | D29: Task | E29: Not started
A30: P1-M1-04 | B30: M1 Full extraction | C30: Run the extract at a modest partition count, then scale up. | D30: Task | E30: Not started
A31: P1-M1-05 | B31: M1 Full extraction | C31: Land to a temporary location with the path convention, then publish a manifest last (table, extract id, rows, bytes, partitions, timestamps, snapshot id). | D31: Task | E31: Not started
A32: P1-M1-06 | B32: M1 Full extraction | C32: Validate row counts and a column checksum against Postgres. | D32: Task | E32: Not started
A33: P1-M1-07 | B33: M1 Full extraction | C33: Partition count sweep: 1, 4, 8, 16, 32 (time, Postgres connections, slowest task). | D33: Experiment | E33: Not started
A34: P1-M1-08 | B34: M1 Full extraction | C34: fetchsize sweep: small / default / large (executor memory, round trips). | D34: Experiment | E34: Not started
A35: P1-M1-09 | B35: M1 Full extraction | C35: Table option vs query with a subquery (what Postgres actually executes). | D35: Experiment | E35: Not started
A36: P1-M1-10 | B36: M1 Full extraction | C36: Landing format and compression: Parquet / CSV / JSON x snappy / zstd / none. | D36: Experiment | E36: Not started
A37: P1-M1-11 | B37: M1 Full extraction | C37: Output file size: many small vs few large files (later scan cost on RustFS). | D37: Experiment | E37: Not started
A38: P1-M1-12 | B38: M1 Full extraction | C38: Partition on the unindexed timestamp and observe the effect of the missing index. | D38: Experiment | E38: Not started
A39: P1-M1-13 | B39: M1 Full extraction | C39: All tables extracted with matching counts and checksums; manifest per extract; partition choices justified with evidence. | D39: Exit check | E39: Not started
A40: M2 Incremental extraction
A41: P1-M2-01 | B41: M2 Incremental extraction | C41: Start the lifecycle replayer so Postgres changes continuously. | D41: Task | E41: Not started
A42: P1-M2-02 | B42: M2 Incremental extraction | C42: Choose an extraction strategy per table (watermark on updated_at, monotonic key, change-log polling, snapshot diff) and justify each. | D42: Task | E42: Not started
A43: P1-M2-03 | B43: M2 Incremental extraction | C43: Build the control table: run id, lower/upper bound, status, row counts, start/finish times. | D43: Task | E43: Not started
A44: P1-M2-04 | B44: M2 Incremental extraction | C44: Measure real update lateness and set the overlap window from data. | D44: Task | E44: Not started
A45: P1-M2-05 | B45: M2 Incremental extraction | C45: Extract the window, land with run id, deduplicate on key and latest change. | D45: Task | E45: Not started
A46: P1-M2-06 | B46: M2 Incremental extraction | C46: Implement delete detection (soft-delete flag, tombstones in the change log, periodic full key reconciliation). | D46: Task | E46: Not started
A47: P1-M2-07 | B47: M2 Incremental extraction | C47: Prove idempotency: re-run the same window; fail a run midway and recover on the next run. | D47: Task | E47: Not started
...

Sheet P2_Joins
A1: Project 2: Joins, shuffles and skew
A2: Source: 02-joins-shuffle-skew.md. Edit only the yellow cells: Status (dropdown), Started, Completed, Evidence / notes.
A3: Progress | B3: =IFERROR(COUNTIF($E$6:$E$600,"Done")/(COUNTA($E$6:$E$600)-COUNTIF($E$6:$E$600,"Skipped")),0) -> 0 | C3: =COUNTIF($E$6:$E$600,"Done")&" of "&(COUNTA($E$6:$E$600)-COUNTIF($E$6:$E$600,"Skipped"))&" items done | In progress: "&COUNTIF($E$6:$E$600,"In progress")&" | Blocked: "&COUNTIF($E$6:$E$600,"Blocked")&" | Skipped: "&COUNTIF($E$6:$E$600,"Skipped") -> 0 of 91 items done | In progress: 0 | Blocked: 0 | Skipped: 0
A5: ID | B5: Milestone | C5: Task | D5: Type | E5: Status | F5: Started | G5: Completed | H5: Evidence / notes
A6: M0 Test bed and baselines
A7: P2-M0-01 | B7: M0 Test bed and baselines | C7: Freeze the data version: record Iceberg snapshot ids of lines, orders, products, aisles, departments, users, stores, price book, payments, events. | D7: Task | E7: Not started
A8: P2-M0-02 | B8: M0 Test bed and baselines | C8: Define benchmark queries J1-J8 (reorder rate by dept/aisle; orders by store/day; revenue per store/day; top-10 products per user; co-occurrence; price range join; payments reconciliation; lake x Postgres). | D8: Task | E8: Not started
A9: P2-M0-03 | B9: M0 Test bed and baselines | C9: Profile keys: share of rows held by top 1/10/100 keys (product, aisle, department, store, user, hour/weekday, basket size). | D9: Task | E9: Not started
A10: P2-M0-04 | B10: M0 Test bed and baselines | C10: Build table variants: lines partitioned by month; lines and orders bucketed on order id (several bucket counts); compacted copies. | D10: Task | E10: Not started
A11: P2-M0-05 | B11: M0 Test bed and baselines | C11: Record baselines: run J1-J8 with defaults twice; log time, shuffle bytes, spill, tasks, plan fingerprint. | D11: Task | E11: Not started
A12: P2-M0-06 | B12: M0 Test bed and baselines | C12: Every query has a baseline and plan; key-skew table exists; variants compacted. | D12: Exit check | E12: Not started
A13: M1 Reading baseline plans
A14: P2-M1-01 | B14: M1 Reading baseline plans | C14: Annotate J1-J4 plans: scan, pushed filters, join type, exchange, sort, partial/final aggregate. | D14: Task | E14: Not started
A15: P2-M1-02 | B15: M1 Reading baseline plans | C15: Predict join types and reasons before checking the plan. | D15: Task | E15: Not started
A16: P2-M1-03 | B16: M1 Reading baseline plans | C16: Force sort-merge (disable auto-broadcast and AQE); count exchanges and sorts; compare time. | D16: Task | E16: Not started
A17: P2-M1-04 | B17: M1 Reading baseline plans | C17: Re-enable AQE; find runtime changes in the final plan. | D17: Task | E17: Not started
A18: P2-M1-05 | B18: M1 Reading baseline plans | C18: Note how Iceberg scans appear and which filters are pushed. | D18: Task | E18: Not started
A19: P2-M1-06 | B19: M1 Reading baseline plans | C19: At least 80% of join-type predictions correct; mismatches explained. | D19: Exit check | E19: Not started
A20: M2 Join strategies by hint
A21: P2-M2-01 | B21: M2 Join strategies by hint | C21: Force broadcast, sort-merge and shuffle-hash on product/aisle/department joins; compare. | D21: Task | E21: Not started
A22: P2-M2-02 | B22: M2 Join strategies by hint | C22: Find the largest broadcastable table given driver memory and broadcast timeout. | D22: Task | E22: Not started
A23: P2-M2-03 | B23: M2 Join strategies by hint | C23: Compare shuffle-hash vs sort-merge where the build side fits (time, memory per task, spill). | D23: Task | E23: Not started
A24: P2-M2-04 | B24: M2 Join strategies by hint | C24: Try the nested-loop hint on tiny inputs only. | D24: Task | E24: Not started
A25: P2-M2-05 | B25: M2 Join strategies by hint | C25: Broadcast side sizes: 50k, 1M, 5M rows. | D25: Experiment | E25: Not started
A26: P2-M2-06 | B26: M2 Join strategies by hint | C26: Auto-broadcast threshold: disabled / 10 MB / 100 MB. | D26: Experiment | E26: Not started
A27: P2-M2-07 | B27: M2 Join strategies by hint | C27: Swap the build side by table order or hint. | D27: Experiment | E27: Not started
A28: P2-M2-08 | B28: M2 Join strategies by hint | C28: Best strategy per query with its margin over the default. | D28: Exit check | E28: Not started
A29: M3 Federated joins
A30: P2-M3-01 | B30: M3 Federated joins | C30: Run J8 (lake lines x Postgres products and price book); read what was pushed vs pulled. | D30: Task | E30: Not started
A31: P2-M3-02 | B31: M3 Federated joins | C31: Run it twice and confirm Postgres is hit again each time. | D31: Task | E31: Not started
A32: P2-M3-03 | B32: M3 Federated joins | C32: Cached JDBC read. | D32: Experiment | E32: Not started
A33: P2-M3-04 | B33: M3 Federated joins | C33: Broadcast the JDBC read. | D33: Experiment | E33: Not started
A34: P2-M3-05 | B34: M3 Federated joins | C34: Snapshot the Postgres tables into Iceberg first. | D34: Experiment | E34: Not started
A35: P2-M3-06 | B35: M3 Federated joins | C35: Join inside Postgres via a pushed-down subquery. | D35: Experiment | E35: Not started
A36: P2-M3-07 | B36: M3 Federated joins | C36: Observe Postgres connections, queries, load, locks; test selective vs unselective cases. | D36: Task | E36: Not started
A37: P2-M3-08 | B37: M3 Federated joins | C37: Break-even rule written (queries per hour, data volume) for each approach. | D37: Exit check | E37: Not started
A38: M4 Diagnosing skew
A39: P2-M4-01 | B39: M4 Diagnosing skew | C39: Aggregate and join on product, department, aisle, store, hour and the bulk buyer; record min/median/max task time, slowest-task shuffle read vs median, spill. | D39: Task | E39: Not started
A40: P2-M4-02 | B40: M4 Diagnosing skew | C40: Show skew in four places: a join, a window by user, a MERGE with a hot source key, uneven JDBC partitions. | D40: Task | E40: Not started
A41: P2-M4-03 | B41: M4 Diagnosing skew | C41: Contrast high-cardinality skew (hot product) with low-cardinality skew (21 departments): idle partitions. | D41: Task | E41: Not started
...

Sheet P3_Planner
A1: Project 3: Catalyst and query planning
A2: Source: 03-catalyst-and-query-planning.md. Edit only the yellow cells: Status (dropdown), Started, Completed, Evidence / notes.
A3: Progress | B3: =IFERROR(COUNTIF($E$6:$E$600,"Done")/(COUNTA($E$6:$E$600)-COUNTIF($E$6:$E$600,"Skipped")),0) -> 0 | C3: =COUNTIF($E$6:$E$600,"Done")&" of "&(COUNTA($E$6:$E$600)-COUNTIF($E$6:$E$600,"Skipped"))&" items done | In progress: "&COUNTIF($E$6:$E$600,"In progress")&" | Blocked: "&COUNTIF($E$6:$E$600,"Blocked")&" | Skipped: "&COUNTIF($E$6:$E$600,"Skipped") -> 0 of 79 items done | In progress: 0 | Blocked: 0 | Skipped: 0
A5: ID | B5: Milestone | C5: Task | D5: Type | E5: Status | F5: Started | G5: Completed | H5: Evidence / notes
A6: M0 Variants and query suite
A7: P3-M0-01 | B7: M0 Variants and query suite | C7: Build lines/events variants: unsorted monthly-partitioned; sorted by product; z-ordered (department, hour); unpartitioned sorted; raw Parquet copy in landing. | D7: Task | E7: Not started
A8: P3-M0-02 | B8: M0 Variants and query suite | C8: Compact every variant to the same target file size. | D8: Task | E8: Not started
A9: P3-M0-03 | B9: M0 Variants and query suite | C9: Define Q1-Q12 (point lookup, low selectivity, date + hour, five-way join with selective dimension, bad join order, metadata-only aggregates, window by user, sampled pairs, price range join, JDBC filter + aggregate, UDF in filter, wide vs narrow select). | D9: Task | E9: Not started
A10: P3-M0-04 | B10: M0 Variants and query suite | C10: Record baselines: time, bytes read, files scanned, plan fingerprint. | D10: Task | E10: Not started
A11: P3-M0-05 | B11: M0 Variants and query suite | C11: All variants exist and are compacted; suite runs and is logged. | D11: Exit check | E11: Not started
A12: M1 Plan literacy
A13: P3-M1-01 | B13: M1 Plan literacy | C13: Predict Q1-Q4 plans (scan, pushed filters, joins, exchanges) before reading them. | D13: Task | E13: Not started
A14: P3-M1-02 | B14: M1 Plan literacy | C14: Read parsed, analyzed, optimized and physical plans; compare with predictions. | D14: Task | E14: Not started
A15: P3-M1-03 | B15: M1 Plan literacy | C15: Find constant folding, column pruning, predicate pushdown through a join, limit pushdown. | D15: Task | E15: Not started
A16: P3-M1-04 | B16: M1 Plan literacy | C16: Learn every scan-node field (pushed, read, remaining). | D16: Task | E16: Not started
A17: P3-M1-05 | B17: M1 Plan literacy | C17: Turn off one optimizer rule on a tiny sample; observe; restore. | D17: Task | E17: Not started
A18: P3-M1-06 | B18: M1 Plan literacy | C18: Compare how Iceberg, JDBC and raw Parquet scans look in plans. | D18: Task | E18: Not started
A19: P3-M1-07 | B19: M1 Plan literacy | C19: Learn plan formats: formatted, cost, codegen, SQL tab graph. | D19: Task | E19: Not started
A20: P3-M1-08 | B20: M1 Plan literacy | C20: At least 80% of plan-feature predictions correct. | D20: Exit check | E20: Not started
A21: M2 Iceberg pruning
A22: P3-M2-01 | B22: M2 Iceberg pruning | C22: Q1/Q3 on the partitioned variant: confirm a timestamp filter prunes without naming a partition column (hidden partitioning). | D22: Task | E22: Not started
A23: P3-M2-02 | B23: M2 Iceberg pruning | C23: Compare file-level skipping (min/max) across unsorted, sorted and z-ordered variants for equality and range filters. | D23: Task | E23: Not started
A24: P3-M2-03 | B24: M2 Iceberg pruning | C24: Prove files and bytes scanned vs total with the metadata tables. | D24: Task | E24: Not started
A25: P3-M2-04 | B25: M2 Iceberg pruning | C25: Compare planning vs execution time; build a many-manifest table to test. | D25: Task | E25: Not started
A26: P3-M2-05 | B26: M2 Iceberg pruning | C26: Q6: can count, min and max be answered from metadata in your versions? | D26: Task | E26: Not started
A27: P3-M2-06 | B27: M2 Iceberg pruning | C27: Q2: explain why pruning helps little for a low-selectivity filter. | D27: Task | E27: Not started
A28: P3-M2-07 | B28: M2 Iceberg pruning | C28: Partition transform: month / day / bucket / none. | D28: Experiment | E28: Not started
A29: P3-M2-08 | B29: M2 Iceberg pruning | C29: File size: small / target / large (planning time, RustFS requests). | D29: Experiment | E29: Not started
A30: P3-M2-09 | B30: M2 Iceberg pruning | C30: Filter shapes: equality, range, IN list, OR. | D30: Experiment | E30: Not started
A31: P3-M2-10 | B31: M2 Iceberg pruning | C31: For each query: files skipped, which metadata enabled it, how to improve it. | D31: Exit check | E31: Not started
A32: M3 Runtime filtering
A33: P3-M3-01 | B33: M3 Runtime filtering | C33: Q4 with a selective dimension filter; look for runtime partition pruning and bloom-filter runtime filters. | D33: Task | E33: Not started
A34: P3-M3-02 | B34: M3 Runtime filtering | C34: Toggle each runtime filter setting; record rows scanned and time. | D34: Experiment | E34: Not started
A35: P3-M3-03 | B35: M3 Runtime filtering | C35: Find when the filter is not inserted (non-selective, large build side, unsupported join, unpartitioned fact). | D35: Task | E35: Not started
A36: P3-M3-04 | B36: M3 Runtime filtering | C36: Compare with a manual rewrite (explicit filter on the fact table). | D36: Task | E36: Not started
A37: P3-M3-05 | B37: M3 Runtime filtering | C37: Conditions that trigger each runtime filter described for your tables. | D37: Exit check | E37: Not started
A38: M4 Statistics and cost-based planning
A39: P3-M4-01 | B39: M4 Statistics and cost-based planning | C39: Q5 with cost-based optimization off: record join order and time. | D39: Task | E39: Not started
A40: P3-M4-02 | B40: M4 Statistics and cost-based planning | C40: Collect table and column statistics; enable CBO and join reordering; re-run. | D40: Task | E40: Not started
A41: P3-M4-03 | B41: M4 Statistics and cost-based planning | C41: Read the cost plan; compare estimates with actuals; explain the worst misestimate. | D41: Task | E41: Not started
...

Sheet P4_Perf
A1: Project 4: Executors, memory and I/O performance
A2: Source: 04-executors-memory-io-performance.md. Edit only the yellow cells: Status (dropdown), Started, Completed, Evidence / notes.
A3: Progress | B3: =IFERROR(COUNTIF($E$6:$E$600,"Done")/(COUNTA($E$6:$E$600)-COUNTIF($E$6:$E$600,"Skipped")),0) -> 0 | C3: =COUNTIF($E$6:$E$600,"Done")&" of "&(COUNTA($E$6:$E$600)-COUNTIF($E$6:$E$600,"Skipped"))&" items done | In progress: "&COUNTIF($E$6:$E$600,"In progress")&" | Blocked: "&COUNTIF($E$6:$E$600,"Blocked")&" | Skipped: "&COUNTIF($E$6:$E$600,"Skipped") -> 0 of 91 items done | In progress: 0 | Blocked: 0 | Skipped: 0
A5: ID | B5: Milestone | C5: Task | D5: Type | E5: Status | F5: Started | G5: Completed | H5: Evidence / notes
A6: M0 Workloads and baselines
A7: P4-M0-01 | B7: M0 Workloads and baselines | C7: Define W1-W6: scan-heavy, shuffle-heavy, CPU-heavy (per-line score), memory-heavy (cache + wide aggregation), write-heavy (layout rewrite), mixed user-feature build. | D7: Task | E7: Not started
A8: P4-M0-02 | B8: M0 Workloads and baselines | C8: Instrument every run with Spark UI, Iceberg metadata, RustFS, Postgres and host CPU/memory/disk. | D8: Task | E8: Not started
A9: P4-M0-03 | B9: M0 Workloads and baselines | C9: Record baselines with the default layout, twice each. | D9: Task | E9: Not started
A10: P4-M0-04 | B10: M0 Workloads and baselines | C10: Classify each workload by apparent bottleneck (to test later). | D10: Task | E10: Not started
A11: P4-M0-05 | B11: M0 Workloads and baselines | C11: Each workload has a stable baseline (under 10% variation) and a first bottleneck guess. | D11: Exit check | E11: Not started
A12: M1 Topology and strong scaling
A13: P4-M1-01 | B13: M1 Topology and strong scaling | C13: Layout: 4 executors x (2 cores, 1 GB). | D13: Experiment | E13: Not started
A14: P4-M1-02 | B14: M1 Topology and strong scaling | C14: Layout: 8 executors x (1 core, 1 GB). | D14: Experiment | E14: Not started
A15: P4-M1-03 | B15: M1 Topology and strong scaling | C15: Layout: 4 executors x (2 cores, 2 GB). | D15: Experiment | E15: Not started
A16: P4-M1-04 | B16: M1 Topology and strong scaling | C16: Layout: 8 executors x (1 core, 512 MB). | D16: Experiment | E16: Not started
A17: P4-M1-05 | B17: M1 Topology and strong scaling | C17: Run W1-W4 on each layout; record time, spill, GC. | D17: Task | E17: Not started
A18: P4-M1-06 | B18: M1 Topology and strong scaling | C18: Strong scaling with 1, 2, 4, 8 total cores; compute speedup and efficiency; find where it flattens. | D18: Task | E18: Not started
A19: P4-M1-07 | B19: M1 Topology and strong scaling | C19: Diagnose the flat part: CPU-bound, storage-bound, source-bound or shuffle-bound. | D19: Task | E19: Not started
A20: P4-M1-08 | B20: M1 Topology and strong scaling | C20: Compare best layout for shuffle-heavy vs scan-heavy; note memory per task. | D20: Task | E20: Not started
A21: P4-M1-09 | B21: M1 Topology and strong scaling | C21: Scaling curve for each workload and a named bottleneck. | D21: Exit check | E21: Not started
A22: M2 Memory model
A23: P4-M2-01 | B23: M2 Memory model | C23: Read the Executors tab: storage memory, execution memory, GC time per task. | D23: Task | E23: Not started
A24: P4-M2-02 | B24: M2 Memory model | C24: Run W4; record cached fraction, spill and GC share. | D24: Task | E24: Not started
A25: P4-M2-03 | B25: M2 Memory model | C25: spark.memory.fraction: 0.4 / 0.6 / 0.8. | D25: Experiment | E25: Not started
A26: P4-M2-04 | B26: M2 Memory model | C26: spark.memory.storageFraction: 0.2 / 0.5 / 0.8. | D26: Experiment | E26: Not started
A27: P4-M2-05 | B27: M2 Memory model | C27: Off-heap memory: off vs on with a fixed size. | D27: Experiment | E27: Not started
A28: P4-M2-06 | B28: M2 Memory model | C28: GC algorithm via executor Java options: default vs parallel. | D28: Experiment | E28: Not started
A29: P4-M2-07 | B29: M2 Memory model | C29: Executor memory: 512m / 1g / 2g. | D29: Experiment | E29: Not started
A30: P4-M2-08 | B30: M2 Memory model | C30: Cause an out-of-memory failure on purpose; learn its signature in the error and UI. | D30: Task | E30: Not started
A31: P4-M2-09 | B31: M2 Memory model | C31: Note that memory overhead is not enforced in standalone; record the implication for YARN/Kubernetes. | D31: Task | E31: Not started
A32: P4-M2-10 | B32: M2 Memory model | C32: From task metrics you can say whether memory, GC or spill is the issue and what to change. | D32: Exit check | E32: Not started
A33: M3 Serialization and RDD
A34: P4-M3-01 | B34: M3 Serialization and RDD | C34: Same aggregation: group-by-key vs reduce-by-key vs DataFrame (shuffle bytes, time). | D34: Experiment | E34: Not started
A35: P4-M3-02 | B35: M3 Serialization and RDD | C35: Switch the serializer and explain why DataFrames barely change. | D35: Experiment | E35: Not started
A36: P4-M3-03 | B36: M3 Serialization and RDD | C36: Persistence levels on an RDD and a DataFrame cache. | D36: Experiment | E36: Not started
A37: P4-M3-04 | B37: M3 Serialization and RDD | C37: Shuffle compression codecs: lz4 / zstd / snappy on W2. | D37: Experiment | E37: Not started
A38: P4-M3-05 | B38: M3 Serialization and RDD | C38: Shuffle buffer settings. | D38: Experiment | E38: Not started
A39: P4-M3-06 | B39: M3 Serialization and RDD | C39: Rules for when RDD tricks help and when to stay with DataFrames. | D39: Exit check | E39: Not started
A40: M4 Python UDF ladder
A41: P4-M4-01 | B41: M4 Python UDF ladder | C41: Choose two per-row computations: math-heavy reorder-propensity score and product-name normalization + tokenization. | D41: Task | E41: Not started
...

Sheet P5_Streaming
A1: Project 5: Streaming and CDC into Iceberg
A2: Source: 05-streaming-cdc-lakehouse.md. Edit only the yellow cells: Status (dropdown), Started, Completed, Evidence / notes.
A3: Progress | B3: =IFERROR(COUNTIF($E$6:$E$600,"Done")/(COUNTA($E$6:$E$600)-COUNTIF($E$6:$E$600,"Skipped")),0) -> 0 | C3: =COUNTIF($E$6:$E$600,"Done")&" of "&(COUNTA($E$6:$E$600)-COUNTIF($E$6:$E$600,"Skipped"))&" items done | In progress: "&COUNTIF($E$6:$E$600,"In progress")&" | Blocked: "&COUNTIF($E$6:$E$600,"Blocked")&" | Skipped: "&COUNTIF($E$6:$E$600,"Skipped") -> 0 of 77 items done | In progress: 0 | Blocked: 0 | Skipped: 0
A5: ID | B5: Milestone | C5: Task | D5: Type | E5: Status | F5: Started | G5: Completed | H5: Evidence / notes
A6: M0 Sources, speeds, SLOs
A7: P5-M0-01 | B7: M0 Sources, speeds, SLOs | C7: Clickstream producer around real baskets, with duplicates/replays, malformed lines, schema drift, out-of-order events and ~2% very late events. | D7: Task | E7: Not started
A8: P5-M0-02 | B8: M0 Sources, speeds, SLOs | C8: Write files safely (temporary name then rename); decide the object naming convention. | D8: Task | E8: Not started
A9: P5-M0-03 | B9: M0 Sources, speeds, SLOs | C9: Run the lifecycle replayer with an adjustable time-compression factor. | D9: Task | E9: Not started
A10: P5-M0-04 | B10: M0 Sources, speeds, SLOs | C10: Verify the change log is ordered and complete. | D10: Task | E10: Not started
A11: P5-M0-05 | B11: M0 Sources, speeds, SLOs | C11: Choose three speeds: low (below capacity), medium (near), high (above). | D11: Task | E11: Not started
A12: P5-M0-06 | B12: M0 Sources, speeds, SLOs | C12: Define service levels before building: freshness, completeness, duplicates, late-data tolerance. | D12: Task | E12: Not started
A13: P5-M0-07 | B13: M0 Sources, speeds, SLOs | C13: Prepare batch reference truth for windows, sessions and current state. | D13: Task | E13: Not started
A14: P5-M0-08 | B14: M0 Sources, speeds, SLOs | C14: Producers run at three speeds; change log verified; service levels written down. | D14: Exit check | E14: Not started
A15: M1 Clickstream to bronze
A16: P5-M1-01 | B16: M1 Clickstream to bronze | C16: File stream with an explicit schema and a files-per-trigger cap; decide how to treat corrupt lines and the drifted field. | D16: Task | E16: Not started
A17: P5-M1-02 | B17: M1 Clickstream to bronze | C17: Write to Iceberg bronze with the checkpoint stored in RustFS. | D17: Task | E17: Not started
A18: P5-M1-03 | B18: M1 Clickstream to bronze | C18: Inspect the checkpoint folder (offsets, commits, sources, metadata) and write down what each represents. | D18: Task | E18: Not started
A19: P5-M1-04 | B19: M1 Clickstream to bronze | C19: Triggers: fixed interval vs available-now vs once. | D19: Experiment | E19: Not started
A20: P5-M1-05 | B20: M1 Clickstream to bronze | C20: Prove exactly-once: restart several times (also mid-batch); compare bronze count with a batch read of the same objects. | D20: Task | E20: Not started
A21: P5-M1-06 | B21: M1 Clickstream to bronze | C21: Watch progress metrics: input rate, processing rate, batch id, duration breakdown. | D21: Task | E21: Not started
A22: P5-M1-07 | B22: M1 Clickstream to bronze | C22: Listing cost as the landing prefix grows; cleanup options (off / archive / delete). | D22: Experiment | E22: Not started
A23: P5-M1-08 | B23: M1 Clickstream to bronze | C23: Decide bronze partitioning (ingestion day, hour, none) and predict file counts. | D23: Task | E23: Not started
A24: P5-M1-09 | B24: M1 Clickstream to bronze | C24: Restarts never lose or duplicate; batch metrics understood; counts match batch reads. | D24: Exit check | E24: Not started
A25: M2 Small files and maintenance
A26: P5-M2-01 | B26: M2 Small files and maintenance | C26: After an hour at medium speed count data files and snapshots in bronze. | D26: Task | E26: Not started
A27: P5-M2-02 | B27: M2 Small files and maintenance | C27: Run compaction and snapshot expiry while the stream runs; record conflicts and retries. | D27: Experiment | E27: Not started
A28: P5-M2-03 | B28: M2 Small files and maintenance | C28: Sink options: fanout vs sorted write; target file size; distribution mode. | D28: Experiment | E28: Not started
A29: P5-M2-04 | B29: M2 Small files and maintenance | C29: Find the trigger interval that meets both freshness and file-count targets. | D29: Task | E29: Not started
A30: P5-M2-05 | B30: M2 Small files and maintenance | C30: Design the maintenance schedule (cadence, order, safe windows, margins relative to the checkpoint). | D30: Task | E30: Not started
A31: P5-M2-06 | B31: M2 Small files and maintenance | C31: Schedule runs while the stream is live with a recorded conflict count; bronze stays within file-count targets. | D31: Exit check | E31: Not started
A32: M3 Windowed aggregates
A33: P5-M3-01 | B33: M3 Windowed aggregates | C33: One-minute tumbling and five-minute sliding counts by event type with a ten-minute watermark. | D33: Task | E33: Not started
A34: P5-M3-02 | B34: M3 Windowed aggregates | C34: Find which output modes the Iceberg sink supports; route upserts through a batch-by-batch merge. | D34: Task | E34: Not started
A35: P5-M3-03 | B35: M3 Windowed aggregates | C35: Watermark 1 min / 10 min / 1 h: emission delay, dropped rows, state size. | D35: Experiment | E35: Not started
A36: P5-M3-04 | B36: M3 Windowed aggregates | C36: Reconcile dropped rows with the producer's known late events. | D36: Task | E36: Not started
A37: P5-M3-05 | B37: M3 Windowed aggregates | C37: Tumbling vs sliding state size. | D37: Experiment | E37: Not started
A38: P5-M3-06 | B38: M3 Windowed aggregates | C38: Compare the stream result with batch truth. | D38: Task | E38: Not started
A39: P5-M3-07 | B39: M3 Windowed aggregates | C39: Stream matches batch except rows beyond the watermark, and you can explain the difference exactly. | D39: Exit check | E39: Not started
A40: M4 Sessionization
A41: P5-M4-01 | B41: M4 Sessionization | C41: 30-minute-gap sessions per user into gold: events, cart adds, conversions, revenue, start, end. | D41: Task | E41: Not started
...

Sheet Environment
A1: Environment and versions
A2: Record what you actually pinned. Do NOT store passwords or keys in this file.
A4: Item | B4: Suggested (from the guide) | C4: Chosen / pinned | D4: Date pinned | E4: Verified how | F4: Notes
A5: Spark version | B5: 4.x (see Gate A)
A6: Scala version | B6: 2.13
A7: Java version | B7: 17 or 21 (confirm in Spark docs)
A8: Hadoop version bundled with Spark | B8: from your Spark distribution
A9: Iceberg Spark runtime artifact and version | B9: must match Spark minor version
A10: S3 access bundle (hadoop-aws + AWS SDK, or Iceberg AWS bundle) | B10: versions must match Hadoop
A11: PostgreSQL version
A12: PostgreSQL JDBC driver version
A13: RustFS release tag | B13: pin a tag, not latest
A14: Catalog type | B14: JDBC on Postgres (recommended)
A15: Source database name
A16: Catalog database name | B16: separate from source
A17: Spark executor layout | B17: 4 x (2 cores, 1 GB) to start
A18: Default shuffle partitions chosen | B18: 16 to 32 for 8 cores (data dependent)
A19: Port: Spark master / master UI | B19: 7077 / 8080
A20: Port: application UI / history server | B20: 4040 / 18080
A21: Port: RustFS S3 API / console | B21: 9000 / 9001
A22: Port: PostgreSQL / Jupyter | B22: 5432 / 8888
A23: Where credentials are stored (do NOT write them here) | B23: e.g. a password manager or env file
A25: Dataset tiers built
A26: Tier | B26: Orders | C26: Order lines | D26: Lines per order | E26: Built on | F26: Random seed | G26: Notes
A27: Example (M, full data) | B27: 3421083 | C27: 33819106 | D27: =IFERROR(C27/B27,"") -> 9.8854971 | E27: 2026-11-02 | F27: 42 | G27: EXAMPLE - overwrite with your own build
A28: S | D28: =IFERROR(C28/B28,"") | G28: ~10% of users, all of their orders (about 340k orders, 3.4M lines)
A29: M | D29: =IFERROR(C29/B29,"") | G29: full dataset (3.42M orders, about 33.8M lines)
A30: L | D30: =IFERROR(C30/B30,"") | G30: full dataset replicated ~3 times (about 10M orders, 100M lines)

Sheet Experiments
A1: Experiment log
A2: One row per experiment. Write the prediction BEFORE you run it. Row 6 is an example; overwrite or delete it.
A5: Exp ID | B5: Date | C5: Project | D5: Milestone | E5: Prediction (before running) | F5: Setting changed | G5: Baseline | H5: Result (time / bytes / shuffle / spill) | I5: Spark UI evidence | J5: Iceberg / RustFS / Postgres evidence | K5: Conclusion | L5: Follow-up | M5: Prediction correct?
A6: E-EX | B6: 2026-11-02 | C6: P2 | D6: M5 Skew-fix ladder | E6: AQE skew join will cut the max task time by half on the product-id join | F6: skewJoin thresholds lowered to 32 MB | G6: max/median task ratio 14x, 212 s | H6: ratio 3x, 96 s, shuffle read 18 GB | I6: Stage 7 task table; SQL plan shows skew=true | J6: RustFS GET count unchanged; Postgres idle | K6: AQE helps the join; no effect on the skewed aggregation | L6: Try salting on the aggregation | M6: Partly

Sheet Defects
A1: Defect register
A2: Pre-filled with the Instacart issues to verify. Change Status to Confirmed / Handled / Not found as you profile. Row 6 is an example.
A5: ID | B5: Table | C5: Column(s) | D5: Description | E5: Rows affected | F5: Table rows | G5: % of rows | H5: Severity | I5: How detected | J5: Handling rule | K5: Layer handled | L5: Proving test | M5: Status
A6: D-EX | B6: orders | C6: days_since_prior_order | D6: Null for each user's first order | E6: 206209 | F6: 3421083 | G6: =IF(AND(ISNUMBER(E6),ISNUMBER(F6),F6>0),E6/F6,"") -> 0.060275942 | H6: Low | I6: Null rate by order_number | J6: Keep null; derive is_first_order | K6: Silver | L6: Assert nulls only where order_number = 1 | M6: Handled
A7: D-001 | B7: orders | C7: eval_set | D7: Test-set orders have no order lines at all | G7: =IF(AND(ISNUMBER(E7),ISNUMBER(F7),F7>0),E7/F7,"") | H7: Medium | I7: Anti-join of orders to both lines files | J7: Keep in orders, flag has_lines = false, exclude from basket metrics | K7: Silver | M7: To verify
A8: D-002 | B8: order_products | C8: order_id | D8: Lines are split across two files (prior and train) that must be unioned | G8: =IF(AND(ISNUMBER(E8),ISNUMBER(F8),F8>0),E8/F8,"") | H8: Medium | I8: File inventory and row counts per file | J8: Union with a source-file column | K8: Bronze | M8: To verify
A9: D-003 | B9: orders | C9: days_since_prior_order | D9: Null for each user's first order | G9: =IF(AND(ISNUMBER(E9),ISNUMBER(F9),F9>0),E9/F9,"") | H9: Low | I9: Null rate by order_number | J9: Keep null; derive is_first_order | K9: Silver | M9: To verify
A10: D-004 | B10: orders | C10: days_since_prior_order | D10: Values appear capped near 30 days (censored data) | G10: =IF(AND(ISNUMBER(E10),ISNUMBER(F10),F10>0),E10/F10,"") | H10: Medium | I10: Value histogram spike at the cap | J10: Treat the cap as 'at least 30'; document in cadence mart | K10: Gold | M10: To verify
A11: D-005 | B11: orders | C11: order_dow, order_hour_of_day | D11: No timestamps: only weekday, hour and gap since previous order | G11: =IF(AND(ISNUMBER(E11),ISNUMBER(F11),F11>0),E11/F11,"") | H11: High | I11: Schema review | J11: Rebuilt timeline with quality flag | K11: Source | M11: To verify
A12: D-006 | B12: products | C12: aisle_id, department_id | D12: Placeholder 'missing' aisle and department | G12: =IF(AND(ISNUMBER(E12),ISNUMBER(F12),F12>0),E12/F12,"") | H12: Medium | I12: Distinct taxonomy values | J12: Map to explicit 'unknown' | K12: Silver | M12: To verify
A13: D-007 | B13: products | C13: product_name | D13: Names contain commas and quotes that break naive CSV parsing | G13: =IF(AND(ISNUMBER(E13),ISNUMBER(F13),F13>0),E13/F13,"") | H13: Low | I13: Compare naive vs quoted-CSV row counts | J13: Use a quoted-CSV reader | K13: Landing | M13: To verify
A14: D-008 | B14: order_products | C14: order_id | D14: Long tail of very large baskets | G14: =IF(AND(ISNUMBER(E14),ISNUMBER(F14),F14>0),E14/F14,"") | H14: Low | I14: Basket-size distribution | J14: Cap or prune in co-occurrence work | K14: Gold | M14: To verify
A15: D-009 | B15: order_products | C15: reordered | D15: Possible disagreements between the reordered flag and user history | G15: =IF(AND(ISNUMBER(E15),ISNUMBER(F15),F15>0),E15/F15,"") | H15: Medium | I15: Rebuild flag from history and compare | J15: Quarantine or flag disagreements | K15: Silver | M15: To verify
A16: D-010 | B16: orders | C16: order_number | D16: User histories may not line up with order_number (gaps or duplicates) | G16: =IF(AND(ISNUMBER(E16),ISNUMBER(F16),F16>0),E16/F16,"") | H16: Medium | I16: Contiguity check per user | J16: Quarantine impossible histories | K16: Silver | M16: To verify
A17: D-011 | B17: (all) | C17: price, payment, store, user | D17: No prices, payments, stores or user attributes exist in the source | G17: =IF(AND(ISNUMBER(E17),ISNUMBER(F17),F17>0),E17/F17,"") | H17: High | I17: Schema review | J17: Generate synthetic tables with documented rules | K17: Source | M17: To verify
G18: =IF(AND(ISNUMBER(E18),ISNUMBER(F18),F18>0),E18/F18,"")
G19: =IF(AND(ISNUMBER(E19),ISNUMBER(F19),F19>0),E19/F19,"")
G20: =IF(AND(ISNUMBER(E20),ISNUMBER(F20),F20>0),E20/F20,"")
G21: =IF(AND(ISNUMBER(E21),ISNUMBER(F21),F21>0),E21/F21,"")
G22: =IF(AND(ISNUMBER(E22),ISNUMBER(F22),F22>0),E22/F22,"")
G23: =IF(AND(ISNUMBER(E23),ISNUMBER(F23),F23>0),E23/F23,"")
G24: =IF(AND(ISNUMBER(E24),ISNUMBER(F24),F24>0),E24/F24,"")
G25: =IF(AND(ISNUMBER(E25),ISNUMBER(F25),F25>0),E25/F25,"")
G26: =IF(AND(ISNUMBER(E26),ISNUMBER(F26),F26>0),E26/F26,"")
G27: =IF(AND(ISNUMBER(E27),ISNUMBER(F27),F27>0),E27/F27,"")
G28: =IF(AND(ISNUMBER(E28),ISNUMBER(F28),F28>0),E28/F28,"")
G29: =IF(AND(ISNUMBER(E29),ISNUMBER(F29),F29>0),E29/F29,"")
... G60: =IF(AND(ISNUMBER(E60),ISNUMBER(F60),F60>0),E60/F60,"")

Sheet Decisions
A1: Decision log
A2: Decisions you must make during the lab. Fill in Evidence (experiment IDs), Choice and Status. Row 6 is an example.
A5: ID | B5: Date | C5: Decision needed | D5: Options considered | E5: Evidence (experiment IDs) | F5: Choice | G5: Revisit if | H5: Status
A6: DEC-EX | B6: 2026-11-02 | C6: Bronze partitioning for lines | D6: month of order date / bucket on order id / unpartitioned sorted | E6: E-021, E-022 | F6: month of order date | G6: date filters stop dominating queries | H6: Decided
A7: DEC-001 | C7: Spark version vs Iceberg runtime (Gate A) | D7: Spark 4.2 if the runtime exists; else newest 4.x with a published Iceberg runtime | H7: Open
A8: DEC-002 | C8: Catalog (Gate D) | D8: Hadoop / JDBC on Postgres / standalone REST / RustFS built-in S3 Tables (preview) | H8: Open
A9: DEC-003 | C9: Jar delivery (Gate C) | D9: Baked into the image vs resolved at runtime | H9: Open
A10: DEC-004 | C10: S3 access path | D10: Hadoop S3A + AWS SDK bundle vs Iceberg's own S3 file I/O | H10: Open
A11: DEC-005 | C11: S tier sampling method | D11: By user (recommended) vs by order | H11: Open
A12: DEC-006 | C12: Postgres lines table design | D12: Single table vs partitioned by order date | H12: Open
A13: DEC-007 | C13: Handling of test-set orders | D13: Keep / flag / separate table | H13: Open
A14: DEC-008 | C14: JDBC partitioning for order_items | D14: Order-id ranges / hash / month / surrogate key | H14: Open
A15: DEC-009 | C15: Snapshot consistency for the full extract | D15: Shared repeatable-read snapshot / quiet window / accept and reconcile | H15: Open
A16: DEC-010 | C16: Incremental strategy per table | D16: Watermark / monotonic key / change-log polling / snapshot diff | H16: Open
A17: DEC-011 | C17: Bronze typing | D17: Typed vs all-string | H17: Open
A18: DEC-012 | C18: Bronze partitioning for lines | D18: Month / day of load / bucket on order id / department / unpartitioned sorted | H18: Open
... A20: DEC-014 | C20: Maintenance cadence and snapshot retention | D20: Per table type; balance time travel needs vs storage | H20: Open

Sheet Config_Cards
A1: Configuration cards
A2: One card per key setting. Defaults come from the configuration map; verify them in the Environment tab of the Spark UI. Fill the yellow cells after an experiment.
A5: Project | B5: Config | C5: Default (verify) | D5: What it controls | E5: Too low / too high | F5: How I observed it | G5: Value chosen and why | H5: Interacts with | I5: Learned?
A6: P1/P2 | B6: spark.sql.shuffle.partitions | C6: 200 | D6: Partitions after a shuffle (joins, aggregates) | I6: Not started
A7: P2/P3 | B7: spark.sql.adaptive.enabled | C7: true | D7: AQE master switch | I7: Not started
A8: P2 | B8: spark.sql.adaptive.advisoryPartitionSizeInBytes | C8: 64MB | D8: Target partition size after coalescing or skew split | I8: Not started
A9: P2 | B9: spark.sql.adaptive.skewJoin.enabled | C9: true | D9: Splits skewed partitions in sort-merge joins | I9: Not started
A10: P2 | B10: spark.sql.autoBroadcastJoinThreshold | C10: 10MB | D10: Auto-broadcast size limit (-1 disables) | I10: Not started
A11: P4 | B11: spark.executor.cores | C11: all worker cores (standalone) | D11: Cores per executor | I11: Not started
A12: P4 | B12: spark.executor.memory | C12: 1g | D12: Executor heap | I12: Not started
A13: P4 | B13: spark.cores.max | C13: unlimited | D13: Total cores an application may take | I13: Not started
A14: P2 | B14: spark.driver.memory | C14: 1g | D14: Driver heap (collect, broadcast build) | I14: Not started
A15: P4 | B15: spark.memory.fraction | C15: 0.6 | D15: Heap share for execution plus storage | I15: Not started
A16: P4 | B16: spark.memory.storageFraction | C16: 0.5 | D16: Part of that share protected for cache | I16: Not started
A17: P1 | B17: JDBC numPartitions | C17: unset | D17: Read/write parallelism and max concurrent connections | I17: Not started
... A38: All | B38: spark.eventLog.enabled / spark.eventLog.dir | C38: false | D38: Event logs for the history server (can point at a bucket) | I38: Not started
